<?xml version="1.0"?>
<robot name="mecanum_bot" xmlns:xacro="http://www.ros.org/wiki/xacro">

  <!-- ================= PARAMETERS ================= -->
  <xacro:property name="chassis_length" value="0.40"/>
  <xacro:property name="chassis_width"  value="0.30"/>
  <xacro:property name="chassis_height" value="0.10"/>
  <xacro:property name="chassis_mass"   value="5.0"/>

  <xacro:property name="wheel_radius"   value="0.05"/>
  <xacro:property name="wheel_width"    value="0.04"/>
  <xacro:property name="wheel_mass"     value="0.5"/>

  <xacro:property name="wheel_x_offset" value="0.15"/>
  <xacro:property name="wheel_y_offset" value="0.18"/>
  <xacro:property name="wheel_z_offset" value="0.0"/>

  <xacro:property name="lidar_radius"   value="0.04"/>
  <xacro:property name="lidar_height"   value="0.05"/>

  <material name="chassis_grey"><color rgba="0.3 0.3 0.3 1.0"/></material>
  <material name="wheel_black"><color rgba="0.05 0.05 0.05 1.0"/></material>
  <material name="lidar_red"><color rgba="0.8 0.0 0.0 1.0"/></material>
  <!-- ================= INERTIA MACROS ================= -->
  <xacro:macro name="box_inertia" params="mass x y z">
    <inertia ixx="${mass/12.0*(y*y+z*z)}" ixy="0.0" ixz="0.0"
             iyy="${mass/12.0*(x*x+z*z)}" iyz="0.0"
             izz="${mass/12.0*(x*x+y*y)}"/>
  </xacro:macro>

  <xacro:macro name="cylinder_inertia" params="mass r h">
    <inertia ixx="${mass/12.0*(3*r*r+h*h)}" ixy="0.0" ixz="0.0"
             iyy="${mass/12.0*(3*r*r+h*h)}" iyz="0.0"
             izz="${mass/2.0*r*r}"/>
  </xacro:macro>

  <link name="base_link">
    <visual>
      <origin xyz="0 0 0" rpy="0 0 0"/>
      <geometry><box size="${chassis_length} ${chassis_width} ${chassis_height}"/></geometry>
      <material name="chassis_grey"/>
    </visual>
    <collision>
      <origin xyz="0 0 0" rpy="0 0 0"/>
      <geometry><box size="${chassis_length} ${chassis_width} ${chassis_height}"/></geometry>
    </collision>
    <inertial>
      <mass value="${chassis_mass}"/>
      <origin xyz="0 0 0" rpy="0 0 0"/>
      <xacro:box_inertia mass="${chassis_mass}" x="${chassis_length}" y="${chassis_width}" z="${chassis_height}"/>
    </inertial>
  </link>

  <gazebo reference="base_link">
    <material>Gazebo/Grey</material>
  </gazebo>
<!-- ================= WHEEL MACRO ================= -->
  <xacro:macro name="wheel" params="prefix x_reflect y_reflect">
    <link name="${prefix}_wheel_link">
      <visual>
        <origin xyz="0 0 0" rpy="${pi/2} 0 0"/>
        <geometry><cylinder radius="${wheel_radius}" length="${wheel_width}"/></geometry>
        <material name="wheel_black"/>
      </visual>
      <collision>
        <origin xyz="0 0 0" rpy="${pi/2} 0 0"/>
        <geometry><cylinder radius="${wheel_radius}" length="${wheel_width}"/></geometry>
      </collision>
      <inertial>
        <mass value="${wheel_mass}"/>
        <origin xyz="0 0 0" rpy="0 0 0"/>
        <xacro:cylinder_inertia mass="${wheel_mass}" r="${wheel_radius}" h="${wheel_width}"/>
      </inertial>
    </link>

    <joint name="${prefix}_wheel_joint" type="continuous">
      <parent link="base_link"/>
      <child link="${prefix}_wheel_link"/>
      <origin xyz="${x_reflect*wheel_x_offset} ${y_reflect*wheel_y_offset} ${wheel_z_offset}" rpy="0 0 0"/>
      <axis xyz="0 1 0"/>
      <dynamics damping="0.1" friction="0.05"/>                                                         
    </joint>

    <gazebo reference="${prefix}_wheel_link">
      <material>Gazebo/Black</material>
      <mu1>0.3</mu1>
      <mu2>0.3</mu2>
    </gazebo>
  </xacro:macro>

  <xacro:wheel prefix="front_left"  x_reflect="1"  y_reflect="1"/>
  <xacro:wheel prefix="front_right" x_reflect="1"  y_reflect="-1"/>
  <xacro:wheel prefix="rear_left"   x_reflect="-1" y_reflect="1"/>
<xacro:wheel prefix="rear_right" x_reflect="-1" y_reflect="-1"/>

  <!-- ================= LIDAR ================= -->
  <link name="lidar_link">
    <visual>
      <origin xyz="0 0 0" rpy="0 0 0"/>
      <geometry><cylinder radius="${lidar_radius}" length="${lidar_height}"/></geometry>
      <material name="lidar_red"/>
    </visual>
    <collision>
      <origin xyz="0 0 0" rpy="0 0 0"/>
      <geometry><cylinder radius="${lidar_radius}" length="${lidar_height}"/></geometry>
    </collision>
    <inertial>
      <mass value="0.1"/>
      <origin xyz="0 0 0" rpy="0 0 0"/>
      <xacro:cylinder_inertia mass="0.1" r="${lidar_radius}" h="${lidar_height}"/>
    </inertial>
  </link>

  <joint name="lidar_joint" type="fixed">
    <parent link="base_link"/>
    <child link="lidar_link"/>
    <origin xyz="0 0 ${chassis_height/2 + lidar_height/2}" rpy="0 0 0"/>
  </joint>

  <gazebo reference="lidar_link">
    <sensor name="lidar_sensor" type="gpu_lidar">
      <pose>0 0 0 0 0 0</pose>
      <topic>scan</topic>
      <update_rate>10</update_rate>
      <ray>
        <scan>
          <horizontal>
            <samples>360</samples>
            <resolution>1</resolution>
            <min_angle>-3.14159</min_angle>
            <max_angle>3.14159</max_angle>
          </horizontal>
        </scan>
        <range>
          <min>0.12</min>
          <max>10.0</max>
          <resolution>0.01</resolution>
        </range>
        <noise>
          <type>gaussian</type>
          <mean>0.0</mean>
          <stddev>0.01</stddev>
        </noise>
      </ray>
      <always_on>true</always_on>
      <visualize>true</visualize>
      <gz_frame_id>lidar_link</gz_frame_id>
    </sensor>
  </gazebo>
 
  <!-- ================= ros2_control ================= -->
  <ros2_control name="GazeboSystem" type="system">
    <hardware>
      <plugin>gz_ros2_control/GazeboSimSystem</plugin>
    </hardware>
    <joint name="front_left_wheel_joint">
      <command_interface name="velocity"/>
      <state_interface name="velocity"/>
      <state_interface name="position"/>
    </joint>
    <joint name="front_right_wheel_joint">
      <command_interface name="velocity"/>
      <state_interface name="velocity"/>
      <state_interface name="position"/>
    </joint>
    <joint name="rear_left_wheel_joint">
      <command_interface name="velocity"/>
      <state_interface name="velocity"/>
      <state_interface name="position"/>
    </joint>
    <joint name="rear_right_wheel_joint">
      <command_interface name="velocity"/>
      <state_interface name="velocity"/>
      <state_interface name="position"/>
    </joint>
  </ros2_control>

  <gazebo>
    <plugin filename="gz_ros2_control-system" name="gz_ros2_control::GazeboSimROS2ControlPlugin">
      <parameters>$(find mecanum_bot)/config/mecanum_controllers.yaml</parameters>
      <robot_param>robot_description</robot_param>
      <robot_param_node>robot_state_publisher</robot_param_node>
    </plugin>
  </gazebo>

</robot>
  
